Workbook

Sheet For Printing
A1: 2 | C1: 3 | G1: 2 | I1: 5 | M1: 9 | P1: 2 | T1: 7
A2: Panel Data / Longitudinal Surveys | C2: Panel Survey Data | G2: Methodological and Measurement Approaches | I2: Intergenerational Income Mobility | M2: Measurement & Methodology | P2: Intergenerational Income Elasticity (IGE) Measures | Q2: 1 | T2: IGE | U2: 1
A3: Administrative / Census / Register Data | C3: Administrative / Census Data | G3: Empirical Estimation of Intergenerational Mobility and Determinants | I3: Intergenerational Wealth Mobility | M3: Determinants and Family/Parental Factors | P3: Rank‐Based Measures | Q3: 2 | T3: RankBased | U3: 2
A4: Survey Data (Cross‐sectional non‐panel) | C4: Rich List Data | G4: Policy and Institutional Effects on Mobility | I4: Role of Education / Human Capital | M4: Role of Education & Human Capital | P4: Transition Matrix / Probability Measures | Q4: 3 | T4: TransitionMatrix | U4: 3
A5: Qualitative / Interview Methods | C5: Qualitative / Mixed Methods | G5: Intergenerational Mobility and Its Consequences on Other Outcomes | I5: Policy and Institutional Effects | M5: Public Policy, Fiscal & Welfare Effects | P5: Absolute Mobility Measures | Q5: 4 | T5: AbsoluteMobility | U5: 4
A6: No Dataset | C6: No dataset | G6: Comparative and Cross-National Studies | I6: Spatial / Geographic Effects | M6: Geographic/Place Effects | P6: Wealth Mobility Measures | T6: StructuralModels | U6: 6
A7: Others | C7: Others | G7: Mobility among Specific Groups (Race, Gender, Immigrants, Family Structure) | I7: Race/Ethnicity/Gender Effects | M7: Intergenerational Wealth Mobility | P7: Multigenerational Mobility Measures | Q7: 4 | T7: NonparametricML | U7: 7
G8: Intergenerational Wealth Mobility and Housing | I8: Methodology and Measurement Approaches | M8: Occupational & Elite Mobility | P8: Subjective Mobility Measures | Q8: 8 | T8: Others | U8: 8
A9: 4 | C9: 5 | G9: Others | I9: Others | M9: Racial/Ethnic/Gender Differences | P9: Others | Q9: 8
A10: Panel Survey Data | C10: National Longitudinal Surveys | M10: Effects on Health & Wellbeing | T10: 8
A11: Administrative/Registry/Tax Data | C11: Administrative/Registry/Census Data | G11: 3 | I11: 6 | M11: Immigration/Migration Effects | P11: 3 | T11: Income Elasticity Measures | U11: 1
A12: Census Data | C12: Specialized Datasets | G12: Measurement and Methodology | I12: Measurement and Methodology | M12: Theoretical Models / Reviews & Multigenerational Models | P12: Intergenerational Income Elasticity (IGE) Measures | Q12: 1 | T12: Rank‐Based Measures | U12: 2
A13: Survey Data | C13: Survey Data | G13: Policy and Institutional Effects | I13: Determinants and Mechanisms | M13: International/Cross-Country Comparisons | P13: Rank‐Based Measures | Q13: 2 | T13: Transition Matrix Measures | U13: 3
A14: Facebook Data | C14: No dataset | G14: Race, Ethnicity and Gender Differences | I14: Policy and Institutional Impact | M14: Effects on Crime & Violence | P14: Transition Matrix/Mobility Rates Measures | Q14: 3 | T14: Structural/Decomposition Model Estimates | U14: 6
A15: Historical/Archival Data | C15: Others | G15: Spatial and Regional Effects | I15: Place and Neighborhood Effects | M15: Political & Attitudinal Effects | P15: Wealth Mobility Measures | T15: Others | U15: 8
A16: Mixed Methods Data | G16: Wealth and Inheritance Transmission | I16: Racial, Ethnic, and Gender Differences | M16: Subjective Perceptions & Attitudes | P16: Sibling Correlation Measures
A17: Pseudo-panel Data | G17: Cross‐Country Comparative Studies | I17: Mobility and Health Outcomes | M17: Historical/Multigenerational Mobility | P17: Others | Q17: 8 | T17: 9
A18: No dataset | G18: Effects on Non‐Income Outcomes | I18: Historical/Multigenerational Studies | M18: Poverty and Disadvantaged Group Mobility | T18: Intergenerational Income Elasticity | U18: 1
A19: Others | G19: Economic Shocks and Structural Changes | I19: Others | M19: Country-Specific Studies | P19: 4 | T19: Rank‐Based Measures | U19: 2
G20: Others | M20: Others | P20: Income Elasticity (IGE) | Q20: 1 | T20: Transition Matrices | U20: 3
A21: 6 | C21: 7 | I21: 7 | P21: Rank-based Measures | Q21: 2 | T21: Absolute Mobility Rates | U21: 4
A22: Panel Survey Data | C22: Administrative/Census/Registry Data | G22: 4 | I22: Measurement and Methodology | M22: 10 | P22: Transition Matrices/Probabilities | Q22: 3 | T22: Others | U22: 8
A23: Administrative Data | C23: Survey/Panel Data | G23: Measurement and Estimation | I23: Empirical Estimates and Trends | M23: Measurement and Methodology | P23: Sibling Correlations
A24: National Household/Census Survey Data | C24: Big Data/Social Media | G24: Role of Education | I24: Determinants and Mechanisms | M24: Trends and Determinants of Income Mobility | P24: Structural/Lifetime Models | Q24: 6 | T24: 10
A25: Social Mobility Project / Big Data | C25: Mixed Methods/Qualitative | G25: Intergenerational Wealth Mobility | I25: Policy and External Shocks | M25: Wealth Mobility | P25: Absolute Mobility Measures | Q25: 4 | T25: IGE-based | U25: 1
A26: Natural Experiment Data | C26: No dataset | G26: Spatial/Neighborhood Effects | I26: Spatial/Geographic Effects | M26: Educational Mobility | P26: Others | Q26: 8 | T26: Rank-based | U26: 2
A27: Qualitative / Interview Data | C27: Others | G27: Racial/Ethnic/Immigrant Differences | I27: Racial, Ethnic, and Immigrant Disparities | M27: Policy and Institutional Effects | T27: Transition Matrix | U27: 3
A28: Pseudo-panel Data | G28: Policy Impacts on Mobility | I28: Social Outcomes (Health, Wellbeing, Crime, etc.) | M28: Spatial/Geographic Effects | P28: 5 | T28: Structural Decomposition | U28: 6
A29: No dataset | G29: Intergenerational Mobility and Health/Wellbeing | I29: Historical and Multigenerational Studies | M29: Demographic and Individual Differences | P29: Income Elasticity Measures | Q29: 1 | T29: Machine Learning/Novel Methods | U29: 8
A30: Others | G30: Gender and Family Structure Effects | I30: Normative and Theoretical Critiques | M30: Effects on Other Outcomes | P30: Rank‐Based Measures | Q30: 2 | T30: Others | U30: 8
G31: Methodology / Sample Issues | I31: Others | M31: Multigenerational Mobility | P31: Transition Matrix / Probability Measures | Q31: 3
A32: 8 | C32: 9 | G32: Multigenerational / Long-run Mobility | M32: Elite Mobility and Class Reproduction | P32: Wealth Mobility Measures
A33: Longitudinal Panel Surveys | C33: Administrative Data | G33: Entrepreneurship and Mobility | I33: 8 | M33: Others | P33: Educational Mobility Measures
A34: Administrative/Register Data | C34: Survey/Panel Data | G34: Financial/Credit Effects | I34: Theoretical and Methodological Approaches | P34: Others | Q34: 8
A35: Survey Data | C35: Historical/Archival Data | G35: Intergenerational Mobility in Developing Countries | I35: Determinants: Family Background and Personal Characteristics
A36: Linked/Combined Data | C36: Combined/Linked Datasets | G36: Intergenerational Mobility in Developed/Post-Soviet Countries | I36: Policy and Institutional Effects | P36: 6
A37: Qualitative/Mixed Methods | C37: Natural/Quasi‐Experimental Data | G37: Global Comparative Analysis | I37: Cross‐Country, Comparative and Historical Studies | P37: Income Elasticity Measures | Q37: 1
A38: Rich List Data | C38: No dataset | G38: Intergenerational Mobility and Trust/Political Attitudes | I38: Race, Gender, and Immigrant Effects | P38: Rank‐Based Measures | Q38: 2
A39: No dataset | C39: Others | G39: Measurement Differences: Absolute vs Relative | I39: Longitudinal/Multigenerational Studies | P39: Transition/Absolute Mobility Measures | Q39: 3
A40: Others | G40: Intergenerational Mobility and Poverty | I40: Effects on Health, Wellbeing and Other Outcomes | P40: Wealth Mobility Measures
...

Sheet RQ
A1: RQ
A2: 2 | B2: Methodological and Measurement Approaches | C2: 1
B3: Empirical Estimation of Intergenerational Mobility and Determinants | C3: 2
B4: Policy and Institutional Effects on Mobility | C4: 3
B5: Intergenerational Mobility and Its Consequences on Other Outcomes | C5: 6
B6: Comparative and Cross-National Studies | C6: 3
B7: Mobility among Specific Groups (Race, Gender, Immigrants, Family Structure) | C7: 5
B8: Intergenerational Wealth Mobility and Housing | C8: 9
B9: Others | C9: 9
A10: 3 | B10: Measurement and Methodology | C10: 1
B11: Policy and Institutional Effects | C11: 3
B12: Race, Ethnicity and Gender Differences | C12: 5
B13: Spatial and Regional Effects | C13: 3
B14: Wealth and Inheritance Transmission | C14: 4
B15: Cross‐Country Comparative Studies | C15: 3
B16: Effects on Non‐Income Outcomes | C16: 6
B17: Economic Shocks and Structural Changes | C17: 7
B18: Others | C18: 9
A19: 4 | B19: Measurement and Estimation | C19: 2
B20: Role of Education | C20: 2
B21: Intergenerational Wealth Mobility | C21: None
B22: Spatial/Neighborhood Effects | C22: 3
B23: Racial/Ethnic/Immigrant Differences | C23: 5
B24: Policy Impacts on Mobility | C24: 3
B25: Intergenerational Mobility and Health/Wellbeing | C25: 6
B26: Gender and Family Structure Effects | C26: 5
B27: Methodology / Sample Issues | C27: 1
B28: Multigenerational / Long-run Mobility | C28: 9
B29: Entrepreneurship and Mobility | C29: 9
B30: Financial/Credit Effects | C30: 9
B31: Intergenerational Mobility in Developing Countries | C31: 3
B32: Intergenerational Mobility in Developed/Post-Soviet Countries | C32: 3
B33: Global Comparative Analysis | C33: 3
... B41: Others | C41: 9
A42: 5 | B42: Intergenerational Income Mobility | C42: None
B43: Intergenerational Wealth Mobility | C43: None
B44: Role of Education / Human Capital | C44: 2
B45: Policy and Institutional Effects | C45: 3
B46: Spatial / Geographic Effects | C46: 3
B47: Race/Ethnicity/Gender Effects | C47: 5
...

Sheet data
A1: Data
A2: 2 | B2: Panel Data / Longitudinal Surveys | C2: 1
B3: Administrative / Census / Register Data | C3: 2
B4: Survey Data (Cross‐sectional non‐panel) | C4: 3
B5: Qualitative / Interview Methods | C5: 14
B6: No Dataset | C6: 13
B7: Others | C7: 14
A8: 3 | B8: Panel Survey Data | C8: 1
B9: Administrative / Census Data | C9: 2
B10: Rich List Data | C10: 8
B11: Qualitative / Mixed Methods | C11: 14
B12: No dataset | C12: 13
B13: Others | C13: 14
A14: 4 | B14: Panel Survey Data | C14: 1
B15: Administrative/Registry/Tax Data | C15: 2
B16: Census Data | C16: 3
B17: Survey Data | C17: 3
B18: Facebook Data | C18: 12
B19: Historical/Archival Data | C19: 11
B20: Mixed Methods Data | C20: 14
B21: Pseudo-panel Data | C21: 10
B22: No dataset | C22: 13
B23: Others | C23: 14
A24: 5 | B24: National Longitudinal Surveys | C24: 1
B25: Administrative/Registry/Census Data | C25: 2
B26: Specialized Datasets | C26: 14
B27: Survey Data | C27: 3
B28: No dataset | C28: 13
B29: Others | C29: 14
A30: 6 | B30: Panel Survey Data | C30: 1
B31: Administrative Data | C31: 2
B32: National Household/Census Survey Data | C32: 3
B33: Social Mobility Project / Big Data | C33: 12
B34: Natural Experiment Data | C34: 5
B35: Qualitative / Interview Data | C35: 14
B36: Pseudo-panel Data | C36: 10
B37: No dataset | C37: 13
B38: Others | C38: 14
A39: 7 | B39: Administrative/Census/Registry Data | C39: 2
B40: Survey/Panel Data | C40: 1
...

Sheet method
A1: Method
A2: 2 | B2: Intergenerational Income Elasticity (IGE) Measures | C2: 1
B3: Rank‐Based Measures | C3: 2
B4: Transition Matrix / Probability Measures | C4: 3
B5: Absolute Mobility Measures | C5: 4
B6: Wealth Mobility Measures | C6: None
B7: Multigenerational Mobility Measures | C7: 4
B8: Subjective Mobility Measures | C8: 8
B9: Others | C9: 8
A10: 3 | B10: Intergenerational Income Elasticity (IGE) Measures | C10: 1
B11: Rank‐Based Measures | C11: 2
B12: Transition Matrix/Mobility Rates Measures | C12: 3
B13: Wealth Mobility Measures | C13: None
B14: Sibling Correlation Measures | C14: None
B15: Others | C15: 8
A16: 4 | B16: Income Elasticity (IGE) | C16: 1
B17: Rank-based Measures | C17: 2
B18: Transition Matrices/Probabilities | C18: 3
B19: Sibling Correlations | C19: None
B20: Structural/Lifetime Models | C20: 6
B21: Absolute Mobility Measures | C21: 4
B22: Others | C22: 8
A23: 5 | B23: Income Elasticity Measures | C23: 1
B24: Rank‐Based Measures | C24: 2
B25: Transition Matrix / Probability Measures | C25: 3
B26: Wealth Mobility Measures | C26: None
B27: Educational Mobility Measures | C27: None
B28: Others | C28: 8
A29: 6 | B29: Income Elasticity Measures | C29: 1
B30: Rank‐Based Measures | C30: 2
B31: Transition/Absolute Mobility Measures | C31: 3
B32: Wealth Mobility Measures | C32: None
B33: Structural/Multigenerational Models | C33: 6
B34: Others | C34: 8
A35: 7 | B35: IGE | C35: 1
B36: RankBased | C36: 2
B37: TransitionMatrix | C37: 3
B38: AbsoluteMobility | C38: 4
B39: StructuralModels | C39: 6
B40: NonparametricML | C40: 7
...

Sheet Results
A1: Count: Data Types | E1: Count: RQ Types | I1: Count: Methods
A2: Number | B2: Category | C2: Count | E2: Number | F2: Category | G2: Count | I2: Number | J2: Category | K2: Count
A3: 1 | B3: Panel/Longitudinal Surveys | C3: =COUNTIF(data!$C$2:$C$57, A3) -> 8 | E3: 1 | F3: Measurement and Methodological Advances | G3: =COUNTIF(RQ!$C$2:$C$57, E3) -> 6 | I3: 1 | J3: Regression‐based Measures | K3: =COUNTIF(method!$C$2:$C$57, I3) -> 9
A4: 2 | B4: Administrative/Registry Data | C4: =COUNTIF(data!$C$2:$C$57, A4) -> 8 | E4: 2 | F4: Empirical Estimates and Determinants | G4: =COUNTIF(RQ!$C$2:$C$57, E4) -> 5 | I4: 2 | J4: Rank‐based Measures | K4: =COUNTIF(method!$C$2:$C$57, I4) -> 9
A5: 3 | B5: National Survey Data | C5: =COUNTIF(data!$C$2:$C$57, A5) -> 6 | E5: 3 | F5: Policy, Institutional, and Geographic Impacts | G5: =COUNTIF(RQ!$C$2:$C$57, E5) -> 15 | I5: 3 | J5: Transition Matrix / Probability Measures | K5: =COUNTIF(method!$C$2:$C$57, I5) -> 9
A6: 4 | B6: Opportunity Atlas | C6: =COUNTIF(data!$C$2:$C$57, A6) -> 0 | E6: 4 | F6: Intergenerational Wealth Mobility and Inheritance | G6: =COUNTIF(RQ!$C$2:$C$57, E6) -> 1 | I6: 4 | J6: Absolute Mobility Measures | K6: =COUNTIF(method!$C$2:$C$57, I6) -> 5
A7: 5 | B7: Natural/Experimental Data | C7: =COUNTIF(data!$C$2:$C$57, A7) -> 2 | E7: 5 | F7: Demographic Differences in Mobility (Race, Gender, etc) | G7: =COUNTIF(RQ!$C$2:$C$57, E7) -> 6 | I7: 5 | J7: Multigenerational Measures | K7: =COUNTIF(method!$C$2:$C$57, I7) -> 0
A8: 6 | B8: Linked Administrative Data | C8: =COUNTIF(data!$C$2:$C$57, A8) -> 2 | E8: 6 | F8: Mobility and Non-Income Outcomes (Health, Wellbeing, etc) | G8: =COUNTIF(RQ!$C$2:$C$57, E8) -> 5 | I8: 6 | J8: Decomposition / Structural Approaches | K8: =COUNTIF(method!$C$2:$C$57, I8) -> 5
A9: 7 | B9: International Panel Data | C9: =COUNTIF(data!$C$2:$C$57, A9) -> 0 | E9: 7 | F9: Theoretical and Structural Models | G9: =COUNTIF(RQ!$C$2:$C$57, E9) -> 1 | I9: 7 | J9: Non‐parametric Approaches | K9: =COUNTIF(method!$C$2:$C$57, I9) -> 1
A10: 8 | B10: Rich List Data | C10: =COUNTIF(data!$C$2:$C$57, A10) -> 2 | E10: 8 | F10: Perceptions of Mobility and Attitudes | G10: =COUNTIF(RQ!$C$2:$C$57, E10) -> 0 | I10: 8 | J10: Others | K10: =COUNTIF(method!$C$2:$C$57, I10) -> 11
A11: 9 | B11: University/Institution Data | C11: =COUNTIF(data!$C$2:$C$57, A11) -> 0 | E11: 9 | F11: Others | G11: =COUNTIF(RQ!$C$2:$C$57, E11) -> 14 | I11: None | J11: N/A | K11: =COUNTIF(method!$C$2:$C$57, I11) -> 7
A12: 10 | B12: Pseudo-Panel/Household Budget Survey | C12: =COUNTIF(data!$C$2:$C$57, A12) -> 2 | E12: None | F12: N/A | G12: =COUNTIF(RQ!$C$2:$C$57, E12) -> 3 | I12: Total | K12: =SUM(K3:K11) -> 56
A13: 11 | B13: Archival/Historical Data | C13: =COUNTIF(data!$C$2:$C$57, A13) -> 2 | E13: Total | G13: =SUM(G3:G12) -> 56
A14: 12 | B14: Big Data | C14: =COUNTIF(data!$C$2:$C$57, A14) -> 3
A15: 13 | B15: No dataset | C15: =COUNTIF(data!$C$2:$C$57, A15) -> 7
A16: 14 | B16: Others | C16: =COUNTIF(data!$C$2:$C$57, A16) -> 14
A17: None | B17: N/A | C17: =COUNTIF(data!$C$2:$C$57, A17) -> 0
A18: Total | C18: =SUM(C3:C17) -> 56
A20: The number of others larger than 10 already gives the idea that 'data_types' is not that consistent. Although it does consistently mention the first three categories albeit in different ways. | E20: Also here, 'Others' went over 10 although 5 categories occurred ≥5 times. This alludes that probably many papers are still not directly about studying wealth mobility in an empirical way or theoretically studying the methodologies of it. | I20: Multigenerational measures and non-parametric approaches don't appear much. There are 7 N/A's which may indicate that 8 categories are maybe too much to describe the methods that the papers actually discussed in their abstracts. (These N/A's were not related to measuring wealth/income/earning mobility) So also, it shows that some papers probably don't really study mobility as I want.
